Workbook

Sheet YIELD CURVE
C1: Discount Curve Rate | F1: Périodicité : | G1: Floating Rate :
C2: ="Flat_"&C3 -> Flat_0,04 | D2: ZC_Curve | E2: fwd_Curve_Rate | F2: Monthly | G2: Euribor 1M | H2: 0.0198
A3: 1 | B3: =A3&"M" -> 1M | C3: 0.04 | D3: 0.045 | E3: 0.04 | F3: Quarterly | G3: Euribor 3M | H3: 0.0216
A4: 2 | B4: =A4&"M" -> 2M | C4: =$C$3 -> 0.04 | D4: =D3+0.00021 -> 0.04521 | E4: =E3+0.00025 -> 0.04025 | F4: Half-Yearly | G4: Euribor 6M | H4: 0.0222
A5: 3 | B5: =A5&"M" -> 3M | C5: =$C$3 -> 0.04 | D5: =D4+0.00021 -> 0.04542 | E5: =E4+0.00025 -> 0.0405 | F5: Yearly | G5: Euribor 12M | H5: 0.0225
A6: 4 | B6: =A6&"M" -> 4M | C6: =$C$3 -> 0.04 | D6: =D5+0.00021 -> 0.04563 | E6: =E5+0.00025 -> 0.04075
A7: 5 | B7: =A7&"M" -> 5M | C7: =$C$3 -> 0.04 | D7: =D6+0.00021 -> 0.04584 | E7: =E6+0.00025 -> 0.041
A8: 6 | B8: =A8&"M" -> 6M | C8: =$C$3 -> 0.04 | D8: =D7+0.00021 -> 0.04605 | E8: =E7+0.00025 -> 0.04125
A9: 7 | B9: =A9&"M" -> 7M | C9: =$C$3 -> 0.04 | D9: =D8+0.00021 -> 0.04626 | E9: =E8+0.00025 -> 0.0415
A10: 8 | B10: =A10&"M" -> 8M | C10: =$C$3 -> 0.04 | D10: =D9+0.00021 -> 0.04647 | E10: =E9+0.00025 -> 0.04175
A11: 9 | B11: =A11&"M" -> 9M | C11: =$C$3 -> 0.04 | D11: =D10+0.00021 -> 0.04668 | E11: =E10+0.00025 -> 0.042
A12: 10 | B12: =A12&"M" -> 10M | C12: =$C$3 -> 0.04 | D12: =D11+0.00021 -> 0.04689 | E12: =E11+0.00025 -> 0.04225
A13: 11 | B13: =A13&"M" -> 11M | C13: =$C$3 -> 0.04 | D13: =D12+0.00021 -> 0.0471 | E13: =E12+0.00025 -> 0.0425
A14: 12 | B14: =A14&"M" -> 12M | C14: =$C$3 -> 0.04 | D14: =D13+0.00021 -> 0.04731 | E14: =E13+0.00025 -> 0.04275
A15: 13 | B15: =A15&"M" -> 13M | C15: =$C$3 -> 0.04 | D15: =D14+0.00021 -> 0.04752 | E15: =E14+0.00025 -> 0.043
A16: 14 | B16: =A16&"M" -> 14M | C16: =$C$3 -> 0.04 | D16: =D15+0.00021 -> 0.04773 | E16: =E15+0.00025 -> 0.04325
A17: 15 | B17: =A17&"M" -> 15M | C17: =$C$3 -> 0.04 | D17: =D16+0.00021 -> 0.04794 | E17: =E16+0.00025 -> 0.0435
... A122: 120 | B122: =A122&"M" -> 120M | C122: =$C$3 -> 0.04 | D122: =D121+0.00021 -> 0.06999 | E122: =E121+0.00025 -> 0.06975

Sheet PRICING BOND
C3: Maturité: | D3: 5 | E3: Years
C4: Taux du coupon: | D4: 0.05 | J4: Theorical Price: | K4: =SUM(M13:M17) -> 1044.5182
C5: Nominal: | D5: 1000
C6: Périodicité: | D6: Yearly
C7: Discount Curve Rate | D7: Flat_0,04
C8: Base de Calcul: | D8: 30/360 | E8: By default
C11: Generated Cash Flows
B12: Nb Of Cash | C12: Type Of Cash | D12: Principal | E12: Coupon Rate | F12: Discount Rate | G12: Nb OF Days In Period | H12: Nb of Days In Year | I12: Start Date | J12: End Date | K12: Cash Flows | L12: DF: Discount Factor | M12: Discount Cash Flows
B13: 1 | C13: Fixed | D13: =$D$5 -> 1000 | E13: =$D$4 -> 0.05 | F13: ='YIELD CURVE'!$C$3 -> 0.04 | G13: =IF($D$6="Yearly",360,IF($D$6="Monthly",30,IF($D$6="Quarterly",90,180))) -> 360 | H13: 360 | I13: =TODAY() -> 46126 | J13: =I13+G13 -> 46486 | K13: =D13*E13*G13/H13 -> 50 | L13: =1/(1+F13)^B13 -> 0.96153846 | M13: =K13*L13 -> 48.076923
B14: 2 | C14: Fixed | D14: =$D$5 -> 1000 | E14: =$D$4 -> 0.05 | F14: ='YIELD CURVE'!$C$3 -> 0.04 | G14: =IF($D$6="Yearly",360,IF($D$6="Monthly",30,IF($D$6="Quarterly",90,180))) -> 360 | H14: 360 | I14: =J13 -> 46486 | J14: =I14+G14 -> 46846 | K14: =D14*E14*G14/H14 -> 50 | L14: =1/(1+F14)^B14 -> 0.92455621 | M14: =K14*L14 -> 46.227811
B15: 3 | C15: Fixed | D15: =$D$5 -> 1000 | E15: =$D$4 -> 0.05 | F15: ='YIELD CURVE'!$C$3 -> 0.04 | G15: =IF($D$6="Yearly",360,IF($D$6="Monthly",30,IF($D$6="Quarterly",90,180))) -> 360 | H15: 360 | I15: =J14 -> 46846 | J15: =I15+G15 -> 47206 | K15: =D15*E15*G15/H15 -> 50 | L15: =1/(1+F15)^B15 -> 0.88899636 | M15: =K15*L15 -> 44.449818
B16: 4 | C16: Fixed | D16: =$D$5 -> 1000 | E16: =$D$4 -> 0.05 | F16: ='YIELD CURVE'!$C$3 -> 0.04 | G16: =IF($D$6="Yearly",360,IF($D$6="Monthly",30,IF($D$6="Quarterly",90,180))) -> 360 | H16: 360 | I16: =J15 -> 47206 | J16: =I16+G16 -> 47566 | K16: =D16*E16*G16/H16 -> 50 | L16: =1/(1+F16)^B16 -> 0.85480419 | M16: =K16*L16 -> 42.74021
B17: 5 | C17: Fixed | D17: =$D$5 -> 1000 | E17: =$D$4 -> 0.05 | F17: ='YIELD CURVE'!$C$3 -> 0.04 | G17: =IF($D$6="Yearly",360,IF($D$6="Monthly",30,IF($D$6="Quarterly",90,180))) -> 360 | H17: 360 | I17: =J16 -> 47566 | J17: =I17+G17 -> 47926 | K17: =D17+D17*E17*G17/H17 -> 1050 | L17: =1/(1+F17)^B17 -> 0.82192711 | M17: =K17*L17 -> 863.02346

Sheet TRA
C2: Maturité: | D2: 5 | E2: Years
C3: Taux du coupon: | D3: 0.05 | J3: Theorical Price: | K3: =SUM(M12:M16) -> 1050
C4: Nominal: | D4: 1000
C5: Périodicité: | D5: Yearly | J5: Market Price: | K5: 1050
C6: Discount Rate | D6: 0.038806287 | E6: Taux de rendement actuariel
C7: Base de Calcul: | D7: 30/360 | E7: By default
C10: Generated Cash Flows
B11: Nb Of Cash | C11: Type Of Cash | D11: Principal | E11: Coupon Rate | F11: Discount Rate | G11: Nb OF Days In Period | H11: Nb of Days In Year | I11: Start Date | J11: End Date | K11: Cash Flows | L11: DF: Discount Factor | M11: Discount Cash Flows
B12: 1 | C12: Fixed | D12: =$D$4 -> 1000 | E12: =$D$3 -> 0.05 | F12: =$D$6 -> 0.038806287 | G12: =IF($D$5="Yearly",360,IF($D$5="Monthly",30,IF($D$5="Quarterly",90,180))) -> 360 | H12: 360 | I12: =TODAY() -> 46126 | J12: =I12+G12 -> 46486 | K12: =D12*E12*G12/H12 -> 50 | L12: =1/(1+F12)^B12 -> 0.96264338 | M12: =K12*L12 -> 48.132169
B13: 2 | C13: Fixed | D13: =$D$4 -> 1000 | E13: =$D$3 -> 0.05 | F13: =$D$6 -> 0.038806287 | G13: =IF($D$5="Yearly",360,IF($D$5="Monthly",30,IF($D$5="Quarterly",90,180))) -> 360 | H13: 360 | I13: =J12 -> 46486 | J13: =I13+G13 -> 46846 | K13: =D13*E13*G13/H13 -> 50 | L13: =1/(1+F13)^B13 -> 0.92668229 | M13: =K13*L13 -> 46.334114
B14: 3 | C14: Fixed | D14: =$D$4 -> 1000 | E14: =$D$3 -> 0.05 | F14: =$D$6 -> 0.038806287 | G14: =IF($D$5="Yearly",360,IF($D$5="Monthly",30,IF($D$5="Quarterly",90,180))) -> 360 | H14: 360 | I14: =J13 -> 46846 | J14: =I14+G14 -> 47206 | K14: =D14*E14*G14/H14 -> 50 | L14: =1/(1+F14)^B14 -> 0.89206457 | M14: =K14*L14 -> 44.603229
B15: 4 | C15: Fixed | D15: =$D$4 -> 1000 | E15: =$D$3 -> 0.05 | F15: =$D$6 -> 0.038806287 | G15: =IF($D$5="Yearly",360,IF($D$5="Monthly",30,IF($D$5="Quarterly",90,180))) -> 360 | H15: 360 | I15: =J14 -> 47206 | J15: =I15+G15 -> 47566 | K15: =D15*E15*G15/H15 -> 50 | L15: =1/(1+F15)^B15 -> 0.85874006 | M15: =K15*L15 -> 42.937003
B16: 5 | C16: Fixed | D16: =$D$4 -> 1000 | E16: =$D$3 -> 0.05 | F16: =$D$6 -> 0.038806287 | G16: =IF($D$5="Yearly",360,IF($D$5="Monthly",30,IF($D$5="Quarterly",90,180))) -> 360 | H16: 360 | I16: =J15 -> 47566 | J16: =I16+G16 -> 47926 | K16: =D16+D16*E16*G16/H16 -> 1050 | L16: =1/(1+F16)^B16 -> 0.82666044 | M16: =K16*L16 -> 867.99346
E21: comment trouver le taux de rendement actuariel
D22: =RATE(5,-K12,-K5,D4) -> -0.058320369
D23: =RATE(5,-50,-1050,1000,0,0.05) -> -0.058320369

Sheet Tx FWD
H14: Nj Fwd: | I14: 180
H16: Nj Short: | I16: 360
K17: Twd: | L17: =(((1+I20*(I14+I16)/360)/(1+I18*I16/360))-1)*(360/I14) -> 0.04535865
H18: Tx Court: | I18: 0.0428
H20: Tx Long: | I20: 0.0443

Sheet SWAP DE TAUX
C1: Implémentation du Swap de Taux (Mise en place)
G2: Comment trouver le taux fixed
C4: Ctp1: | D4: TD: | E4: =TODAY() -> 46126 | M4: Ctp2: | N4: TD: | O4: =E4 -> 46126
D5: Maturité: | E5: 5 | F5: Years | N5: Maturité: | O5: =E5 -> 5 | P5: Years
D6: Fixed Rate: | E6: 0.046749163 | N6: Floating Rate: | O6: Euribor 12M
D7: Nominal: | E7: 1000 | N7: Nominal: | O7: =E7 -> 1000
D8: Périodicité: | E8: Yearly | N8: Périodicité: | O8: Yearly
D9: Discount Curve Rate | E9: ZC_Curve | N9: Discount Curve Rate | O9: ZC_Curve
D10: Base de Calcul: | E10: 30/360 | F10: By default | N10: Base de Calcul: | O10: 30/360 | P10: By default
N11: Forward Curve Rate: | O11: ='YIELD CURVE'!E2 -> fwd_Curve_Rate
C13: Implémentation | D13: Generated Cash Flows
C14: Nb Of Cash | D14: Type Of Cash | E14: Principal | F14: FIXED Rate | G14: Floating Rate | H14: Discount Rate | I14: Nb OF Days In Period | J14: Nb of Days In Year | L14: Start Date | M14: End Date | N14: Cash Flows | O14: DF: Discount Factor | P14: Discount Cash Flows
C15: 1 | D15: Fixed | E15: =$E$7 -> 1000 | F15: =$E$6 -> 0.046749163 | G15: ------------ | H15: ='YIELD CURVE'!D14 -> 0.04731 | I15: 360 | J15: 360 | L15: =E4 -> 46126 | M15: =L15+I15 -> 46486 | N15: =F15*E15*I15/J15 -> 46.749163 | O15: =1/(1+H15)^C15 -> 0.95482713 | P15: =N15*O15 -> 44.637369 | R15: Fixed NPV: | S15: =SUM(P15:P19) -> 200.29
C16: 2 | D16: Fixed | E16: =$E$7 -> 1000 | F16: =$E$6 -> 0.046749163 | G16: ------------ | H16: ='YIELD CURVE'!D26 -> 0.04983 | I16: 360 | J16: 360 | L16: =M15 -> 46486 | M16: =L16+I16 -> 46846 | N16: =F16*E16*I16/J16 -> 46.749163 | O16: =1/(1+H16)^C16 -> 0.90732325 | P16: =N16*O16 -> 42.416603
C17: 3 | D17: Fixed | E17: =$E$7 -> 1000 | F17: =$E$6 -> 0.046749163 | G17: ------------ | H17: ='YIELD CURVE'!D38 -> 0.05235 | I17: 360 | J17: 360 | L17: =M16 -> 46846 | M17: =L17+I17 -> 47206 | N17: =F17*E17*I17/J17 -> 46.749163 | O17: =1/(1+H17)^C17 -> 0.85806341 | P17: =N17*O17 -> 40.113746
C18: 4 | D18: Fixed | E18: =$E$7 -> 1000 | F18: =$E$6 -> 0.046749163 | G18: ------------ | H18: ='YIELD CURVE'!D50 -> 0.05487 | I18: 360 | J18: 360 | L18: =M17 -> 47206 | M18: =L18+I18 -> 47566 | N18: =F18*E18*I18/J18 -> 46.749163 | O18: =1/(1+H18)^C18 -> 0.80761474 | P18: =N18*O18 -> 37.755313
C19: 5 | D19: Fixed | E19: =$E$7 -> 1000 | F19: =$E$6 -> 0.046749163 | G19: ------------ | H19: ='YIELD CURVE'!D62 -> 0.05739 | I19: 360 | J19: 360 | L19: =M18 -> 47566 | M19: =L19+I19 -> 47926 | N19: =F19*E19*I19/J19 -> 46.749163 | O19: =1/(1+H19)^C19 -> 0.75652626 | P19: =N19*O19 -> 35.366969
C20: 1 | D20: Floating | E20: =$E$7 -> 1000 | F20: ---------- | G20: ='YIELD CURVE'!H5 -> 0.0225 | H20: ='YIELD CURVE'!$C$3 -> 0.04 | I20: 360 | J20: 360 | L20: =O4 -> 46126 | M20: =L20+I20 -> 46486 | N20: =G20*E20*I20/J20 -> 22.5 | O20: =1/(1+H20)^C20 -> 0.96153846 | P20: =N20*O20 -> 21.634615 | R20: Floating NPV: | S20: =SUM(P20:P24) -> 200.28865
C21: 2 | D21: Floating | E21: =$E$7 -> 1000 | F21: ---------- | G21: 0.0468 | H21: ='YIELD CURVE'!$C$3 -> 0.04 | I21: 360 | J21: 360 | L21: =M20 -> 46486 | M21: =L21+I21 -> 46846 | N21: =G21*E21*I21/J21 -> 46.8 | O21: =1/(1+H21)^C21 -> 0.92455621 | P21: =N21*O21 -> 43.269231
C22: 3 | D22: Floating | E22: =$E$7 -> 1000 | F22: ---------- | G22: 0.0502 | H22: ='YIELD CURVE'!$C$3 -> 0.04 | I22: 360 | J22: 360 | L22: =M21 -> 46846 | M22: =L22+I22 -> 47206 | N22: =G22*E22*I22/J22 -> 50.2 | O22: =1/(1+H22)^C22 -> 0.88899636 | P22: =N22*O22 -> 44.627617
C23: 4 | D23: Floating | E23: =$E$7 -> 1000 | F23: ---------- | G23: 0.053 | H23: ='YIELD CURVE'!$C$3 -> 0.04 | I23: 360 | J23: 360 | L23: =M22 -> 47206 | M23: =L23+I23 -> 47566 | N23: =G23*E23*I23/J23 -> 53 | O23: =1/(1+H23)^C23 -> 0.85480419 | P23: =N23*O23 -> 45.304622
C24: 5 | D24: Floating | E24: =$E$7 -> 1000 | F24: ---------- | G24: 0.0553 | H24: ='YIELD CURVE'!$C$3 -> 0.04 | I24: 360 | J24: 360 | L24: =M23 -> 47566 | M24: =L24+I24 -> 47926 | N24: =G24*E24*I24/J24 -> 55.3 | O24: =1/(1+H24)^C24 -> 0.82192711 | P24: =N24*O24 -> 45.452569
C27: Fonctionnement | D27: Generated Cash Flows
C28: Nb Of Cash | D28: Type Of Cash | E28: Principal | F28: FIXED Rate | G28: Floating Rate | H28: Discount Rate | I28: Nb OF Days In Period | J28: Nb of Days In Year | K28: Fixing Rate | L28: Start Date | M28: End Date | N28: Cash Flows | O28: DF: Discount Factor | P28: Discount Cash Flows
C29: 1 | D29: Fixed | E29: =$E$7 -> 1000 | F29: =$E$150 -> 0 | G29: ------------ | H29: ='YIELD CURVE'!D28 -> 0.05025 | I29: 360 | J29: 360 | L29: =L15 -> 46126 | M29: =L29+I29 -> 46486 | N29: =N15 -> 46.749163 | O29: =O15 -> 0.95482713 | P29: =P15 -> 44.637369 | R29: Fixed NPV: | S29: =SUM(P29:P33) -> 200.29
C30: 2 | D30: Fixed | E30: =$E$7 -> 1000 | F30: =$E$150 -> 0 | G30: ------------ | H30: ='YIELD CURVE'!D40 -> 0.05277 | I30: 360 | J30: 360 | L30: =L16 -> 46486 | M30: =L30+I30 -> 46846 | N30: =N16 -> 46.749163 | O30: =O16 -> 0.90732325 | P30: =P16 -> 42.416603
C31: 3 | D31: Fixed | E31: =$E$7 -> 1000 | F31: =$E$150 -> 0 | G31: ------------ | H31: ='YIELD CURVE'!D52 -> 0.05529 | I31: 360 | J31: 360 | L31: =L17 -> 46846 | M31: =L31+I31 -> 47206 | N31: =N17 -> 46.749163 | O31: =O17 -> 0.85806341 | P31: =P17 -> 40.113746
C32: 4 | D32: Fixed | E32: =$E$7 -> 1000 | F32: =$E$150 -> 0 | G32: ------------ | H32: ='YIELD CURVE'!D64 -> 0.05781 | I32: 360 | J32: 360 | L32: =L18 -> 47206 | M32: =L32+I32 -> 47566 | N32: =N18 -> 46.749163 | O32: =O18 -> 0.80761474 | P32: =P18 -> 37.755313
C33: 5 | D33: Fixed | E33: =$E$7 -> 1000 | F33: =$E$150 -> 0 | G33: ------------ | H33: ='YIELD CURVE'!D76 -> 0.06033 | I33: 360 | J33: 360 | L33: =L19 -> 47566 | M33: =L33+I33 -> 47926 | N33: =N19 -> 46.749163 | O33: =O19 -> 0.75652626 | P33: =P19 -> 35.366969
C34: 1 | D34: Floating | E34: =$O$7 -> 1000 | F34: ---------- | G34: 0.0225 | H34: ='YIELD CURVE'!$C$3 -> 0.04 | I34: 360 | J34: 360 | K34: =L34 -> 46126 | L34: =L20 -> 46126 | M34: =M20 -> 46486 | N34: =N20 -> 22.5 | O34: =O20 -> 0.96153846 | P34: =N34*O34 -> 21.634615 | R34: Floating NPV: | S34: =SUM(P34:P38) -> 81.409626
C35: 2 | D35: Floating | E35: =$O$7 -> 1000 | F35: ---------- | G35: 0.01 | H35: ='YIELD CURVE'!$C$3 -> 0.04 | I35: 360 | J35: 360 | K35: =L35 -> 46486 | L35: =L21 -> 46486 | M35: =M21 -> 46846 | N35: =G35*E35*I35/J35 -> 10 | O35: =O21 -> 0.92455621 | P35: =N35*O35 -> 9.2455621
C36: 3 | D36: Floating | E36: =$O$7 -> 1000 | F36: ---------- | G36: 0.023 | H36: ='YIELD CURVE'!$C$3 -> 0.04 | I36: 360 | J36: 360 | K36: =L36 -> 46846 | L36: =L22 -> 46846 | M36: =M22 -> 47206 | N36: =G36*E36*I36/J36 -> 23 | O36: =O22 -> 0.88899636 | P36: =N36*O36 -> 20.446916
C37: 4 | D37: Floating | E37: =$O$7 -> 1000 | F37: ---------- | G37: 0.015 | H37: ='YIELD CURVE'!$C$3 -> 0.04 | I37: 360 | J37: 360 | K37: =L37 -> 47206 | L37: =L23 -> 47206 | M37: =M23 -> 47566 | N37: =G37*E37*I37/J37 -> 15 | O37: =O23 -> 0.85480419 | P37: =N37*O37 -> 12.822063
C38: 5 | D38: Floating | E38: =$O$7 -> 1000 | F38: ---------- | G38: 0.021 | H38: ='YIELD CURVE'!$C$3 -> 0.04 | I38: 360 | J38: 360 | K38: =L38 -> 47566 | L38: =L24 -> 47566 | M38: =M24 -> 47926 | N38: =G38*E38*I38/J38 -> 21 | O38: =O24 -> 0.82192711 | P38: =N38*O38 -> 17.260469
C43: CAS 2
C47: Ctp1: | D47: TD: | E47: =TODAY() -> 46126 | M47: Ctp2: | N47: TD: | O47: =E47 -> 46126
D48: Maturité: | E48: 2 | F48: Years | N48: Maturité: | O48: =E48 -> 2 | P48: Years
D49: Fixed Rate: | E49: 0.039758998 | N49: Floating Rate: | O49: Euribor 6M
D50: Nominal: | E50: 1000 | N50: Nominal: | O50: =E50 -> 1000
D51: Périodicité: | E51: Yearly | N51: Périodicité: | O51: Half-Yearly
...
