Workbook

Sheet Contexte

Sheet 31.01
E1: Actif | G1: Montant
E2: Actions | G2: =100000000-G4-G5-G3 -> 80000000
E3: Obligations | G3: 10000000
E4: Monétaire | G4: =0.1*100000000 -> 10000000
B7: Actions
B9: NOMBRES | C9: TITRES | D9: PONDERATION | E9: COURS 27/01 | F9: COURS 31/01 | G9: Nbre d'actions | H9: VALEUR DU PORTEFEUILLE | I9: BETA | J9: Béta pondéré | K9: Performance
B10: 29 | C10: WALLIX GROUP | D10: 0.0145 | E10: 14.9 | F10: 15.88 | G10: =ROUNDDOWN(D10*$G$2/E10,0) -> 77852 | H10: =G10*F10 -> 1236289.8 | I10: 1.38 | J10: =I10*D10 -> 0.02001 | K10: =(F10-E10)/E10 -> 0.065771812
B11: 1 | C11: DANONE | D11: 0.028 | E11: 49.53 | F11: 50.25 | G11: =ROUNDDOWN(D11*$G$2/E11,0) -> 45225 | H11: =G11*F11 -> 2272556.2 | I11: 0.49 | J11: =I11*D11 -> 0.01372 | K11: =(F11-E11)/E11 -> 0.014536644
B12: 12 | C12: KERING | D12: 0.04 | E12: 557.7 | F12: 565.7 | G12: =ROUNDDOWN(D12*$G$2/E12,0) -> 5737 | H12: =G12*F12 -> 3245420.9 | I12: 1.07 | J12: =I12*D12 -> 0.0428 | K12: =(F12-E12)/E12 -> 0.01434463
B13: 16 | C13: PERNOD RICARD | D13: 0.05 | E13: 184.2 | F13: 186.3 | G13: =ROUNDDOWN(D13*$G$2/E13,0) -> 21715 | H13: =G13*F13 -> 4045504.5 | I13: 0.43 | J13: =I13*D13 -> 0.0215 | K13: =(F13-E13)/E13 -> 0.011400651
B14: 17 | C14: DASSAULT | D14: 0.0345 | E14: 33.69 | F14: 34.06 | G14: =ROUNDDOWN(D14*$G$2/E14,0) -> 81923 | H14: =G14*F14 -> 2790297.4 | I14: 0.689 | J14: =I14*D14 -> 0.0237705 | K14: =(F14-E14)/E14 -> 0.010982487
B15: 18 | C15: BNP PARIBAS | D15: 0.015 | E15: 62.03 | F15: 62.66 | G15: =ROUNDDOWN(D15*$G$2/E15,0) -> 19345 | H15: =G15*F15 -> 1212157.7 | I15: 1.73 | J15: =I15*D15 -> 0.02595 | K15: =(F15-E15)/E15 -> 0.010156376
B16: 27 | C16: PUBLICIS GROUPE | D16: 0.05 | E16: 64.46 | F16: 65.04 | G16: =ROUNDDOWN(D16*$G$2/E16,0) -> 62053 | H16: =G16*F16 -> 4035927.1 | I16: 0.913 | J16: =I16*D16 -> 0.04565 | K16: =(F16-E16)/E16 -> 0.0089978281
B17: 24 | C17: ESSILORLUXOTTICA | D17: 0.0145 | E17: 166.15 | F17: 167.25 | G17: =ROUNDDOWN(D17*$G$2/E17,0) -> 6981 | H17: =G17*F17 -> 1167572.2 | I17: 0.912 | J17: =I17*D17 -> 0.013224 | K17: =(F17-E17)/E17 -> 0.0066205236
B18: 11 | C18: BOUYGUES | D18: 0.015 | E18: 30.25 | F18: 30.35 | G18: =ROUNDDOWN(D18*$G$2/E18,0) -> 39669 | H18: =G18*F18 -> 1203954.2 | I18: 0.955 | J18: =I18*D18 -> 0.014325 | K18: =(F18-E18)/E18 -> 0.0033057851
B19: 26 | C19: CATANA GROUPE | D19: 0.01 | E19: 6.48 | F19: 6.5 | G19: =ROUNDDOWN(D19*$G$2/E19,0) -> 123456 | H19: =G19*F19 -> 802464 | I19: 1.7 | J19: =I19*D19 -> 0.017 | K19: =(F19-E19)/E19 -> 0.0030864198
B20: 9 | C20: SANOFI | D20: 0.05 | E20: 89.55 | F20: 89.73 | G20: =ROUNDDOWN(D20*$G$2/E20,0) -> 44667 | H20: =G20*F20 -> 4007969.9 | I20: 0.416 | J20: =I20*D20 -> 0.0208 | K20: =(F20-E20)/E20 -> 0.0020100503
B21: 19 | C21: CARREFOUR | D21: 0.03 | E21: 17.51 | F21: 17.52 | G21: =ROUNDDOWN(D21*$G$2/E21,0) -> 137064 | H21: =G21*F21 -> 2401361.3 | I21: 0.549 | J21: =I21*D21 -> 0.01647 | K21: =(F21-E21)/E21 -> 0.00057110223
B22: 4 | C22: L'OREAL | D22: 0.05 | E22: 378.45 | F22: 378.55 | G22: =ROUNDDOWN(D22*$G$2/E22,0) -> 10569 | H22: =G22*F22 -> 4000895 | I22: 0.604 | J22: =I22*D22 -> 0.0302 | K22: =(F22-E22)/E22 -> 0.0002642357
B23: 10 | C23: HERMES | D23: 0.05 | E23: 1697.5 | F23: 1.692,50 | G23: =ROUNDDOWN(D23*$G$2/E23,0) -> 2356 | H23: =G23*F23 -> 3987530 | I23: 0.657 | J23: =I23*D23 -> 0.03285 | K23: =(F23-E23)/E23 -> -0.0029455081
B24: 6 | C24: AIR LIQUIDE SA | D24: 0.05 | E24: 148.26 | F24: 147.8 | G24: =ROUNDDOWN(D24*$G$2/E24,0) -> 26979 | H24: =G24*F24 -> 3987496.2 | I24: 0.636 | J24: =I24*D24 -> 0.0318 | K24: =(F24-E24)/E24 -> -0.0031026575
B25: 28 | C25: CAPGEMINI | D25: 0.04 | E25: 173 | F25: 172.4 | G25: =ROUNDDOWN(D25*$G$2/E25,0) -> 18497 | H25: =G25*F25 -> 3188882.8 | I25: 1.15 | J25: =I25*D25 -> 0.046 | K25: =(F25-E25)/E25 -> -0.0034682081
B26: 3 | C26: LVMH | D26: 0.05 | E26: 801 | F26: 797.1 | G26: =ROUNDDOWN(D26*$G$2/E26,0) -> 4993 | H26: =G26*F26 -> 3979920.3 | I26: 0.964 | J26: =I26*D26 -> 0.0482 | K26: =(F26-E26)/E26 -> -0.0048689139
B27: 7 | C27: SCHNEIDER ELECTRIC SE | D27: 0.05 | E27: 147.88 | F27: 147.14 | G27: =ROUNDDOWN(D27*$G$2/E27,0) -> 27048 | H27: =G27*F27 -> 3979842.7 | I27: 1 | J27: =I27*D27 -> 0.05 | K27: =(F27-E27)/E27 -> -0.0050040573
B28: 14 | C28: STMicroelectronics | D28: 0.045 | E28: 43.69 | F28: 43.42 | G28: =ROUNDDOWN(D28*$G$2/E28,0) -> 82398 | H28: =G28*F28 -> 3577721.2 | I28: 1.29 | J28: =I28*D28 -> 0.05805 | K28: =(F28-E28)/E28 -> -0.0061799039
B29: 21 | C29: COVIVIO | D29: 0.02 | E29: 63.15 | F29: 62.75 | G29: =ROUNDDOWN(D29*$G$2/E29,0) -> 25336 | H29: =G29*F29 -> 1589834 | I29: 1.43 | J29: =I29*D29 -> 0.0286 | K29: =(F29-E29)/E29 -> -0.0063341251
B30: 13 | C30: SAFRAN | D30: 0.0345 | E30: 132.2 | F30: 131.36 | G30: =ROUNDDOWN(D30*$G$2/E30,0) -> 20877 | H30: =G30*F30 -> 2742402.7 | I30: 1.33 | J30: =I30*D30 -> 0.045885 | K30: =(F30-E30)/E30 -> -0.0063540091
B31: 22 | C31: THALES | D31: 0.05 | E31: 121.3 | F31: 120.45 | G31: =ROUNDDOWN(D31*$G$2/E31,0) -> 32976 | H31: =G31*F31 -> 3971959.2 | I31: 0.635 | J31: =I31*D31 -> 0.03175 | K31: =(F31-E31)/E31 -> -0.0070074196
B32: 8 | C32: VINCI SA | D32: 0.02 | E32: 105.04 | F32: 104.14 | G32: =ROUNDDOWN(D32*$G$2/E32,0) -> 15232 | H32: =G32*F32 -> 1586260.5 | I32: 0.953 | J32: =I32*D32 -> 0.01906 | K32: =(F32-E32)/E32 -> -0.0085681645
B33: 5 | C33: TOTALEnergies SE | D33: 0.05 | E33: 58.62 | F33: 57.89 | G33: =ROUNDDOWN(D33*$G$2/E33,0) -> 68236 | H33: =G33*F33 -> 3950182 | I33: 0.993 | J33: =I33*D33 -> 0.04965 | K33: =(F33-E33)/E33 -> -0.012453088
B34: 23 | C34: Virbac | D34: 0.0145 | E34: 281 | F34: 277.5 | G34: =ROUNDDOWN(D34*$G$2/E34,0) -> 4128 | H34: =G34*F34 -> 1145520 | I34: 0.803 | J34: =I34*D34 -> 0.0116435 | K34: =(F34-E34)/E34 -> -0.012455516
B35: 15 | C35: NEOEN | D35: 0.0445 | E35: 34.69 | F35: 34.22 | G35: =ROUNDDOWN(D35*$G$2/E35,0) -> 102623 | H35: =G35*F35 -> 3511759.1 | I35: 0.847 | J35: =I35*D35 -> 0.0376915 | K35: =(F35-E35)/E35 -> -0.013548573
... B38: 25 | C38: AUBAY | D38: 0.02 | E38: 49.85 | F38: 48 | G38: =ROUNDDOWN(D38*$G$2/E38,0) -> 32096 | H38: =G38*F38 -> 1540608 | I38: 1.36 | J38: =I38*D38 -> 0.0272 | K38: =(F38-E38)/E38 -> -0.037111334
B39: TOTAL | D39: =SUM(D10:D38) -> 1 | H39: =SUM(H10:H38) -> 79823619 | I39: Beta Pondéré | J39: =SUM(J10:J38) -> 0.9189995 | K39: =SUM(Tableau13[[Performance ]]) -> -0.02914416
B41: Obligations
B43: Libellé | C43: Taux Coupon | D43: Maturité | E43: Date Coupon | G43: Rendement | H43: Date achat | I43: Cours du 27/01 | J43: Cours du 31/01 | L43: Pondération | M43: Nbre de titre | N43: Montant | O43: Performance
B44: OAT 10 ans | C44: 0.02 | D44: 48543 | E44: 45255 | G44: 0.02702 | H44: 44953 | I44: 100 | J44: 93.7 | L44: 0.6 | M44: =ROUNDDOWN(L44*$G$3/I44,0) -> 60000 | N44: =M44*J44 -> 5622000 | O44: =(J44-I44)/I44 -> -0.063
B45: OAT 5 ans | C45: 0.0075 | D45: 46898 | E45: 45071 | G45: 0.025388 | H45: 44953 | I45: 91.49 | J45: 90.72 | L45: 0.4 | M45: =ROUNDDOWN(L45*$G$3/I45,0) -> 43720 | N45: =M45*J45 -> 3966278.4 | O45: =(J45-I45)/I45 -> -0.0084162204
I46: TOTAL | N46: =SUM(N44:N45) -> 9588278.4 | O46: =SUM(O44:O45) -> -0.07141622

Sheet 07.02
E1: Actif | H1: Montant
E2: Actions | H2: =100000000-H4-H5-H3 -> 80000000
E3: Obligations | H3: 10000000
E4: Monétaire | H4: =0.1*100000000 -> 10000000
B7: Actions ( après arbitrage)
B9: NOMBRES | C9: TITRES | D9: PONDERATION | E9: COURS 27/01 | F9: COURS 31/01 | G9: COURS 07/02 | H9: Nbre d'actions | I9: VALEUR DU PORTEFEUILLE | J9: BETA | K9: Colonne1 | L9: Colonne2 | M9: Béta pondéré
B10: 27 | C10: PUBLICIS GROUPE | D10: 0.05 | E10: 64.46 | F10: 65.04 | G10: 73.46 | H10: =ROUNDDOWN(D10*$H$2/Tableau1[[#This Row],[COURS 27/01]],0) -> 62053 | I10: =H10*Tableau1[[#This Row],[COURS 07/02]] -> 4558413.4 | J10: 0.913 | M10: =J10*D10 -> 0.04565
B11: 17 | C11: DASSAULT | D11: 0.0345 | E11: 33.69 | F11: 34.06 | G11: 38.05 | H11: =ROUNDDOWN(D11*$H$2/Tableau1[[#This Row],[COURS 27/01]],0) -> 81923 | I11: =H11*Tableau1[[#This Row],[COURS 07/02]] -> 3117170.1 | J11: 0.689 | M11: =J11*D11 -> 0.0237705
B12: 26 | C12: CATANA GROUPE | D12: 0.01 | E12: 6.48 | F12: 6.5 | G12: 7 | H12: =ROUNDDOWN(D12*$H$2/Tableau1[[#This Row],[COURS 27/01]],0) -> 123456 | I12: =H12*Tableau1[[#This Row],[COURS 07/02]] -> 864192 | J12: 1.7 | M12: =J12*D12 -> 0.017
B13: 15 | C13: NEOEN | D13: 0.0445 | E13: 34.69 | F13: 34.22 | G13: 36.76 | H13: =ROUNDDOWN(D13*$H$2/Tableau1[[#This Row],[COURS 27/01]],0) -> 102623 | I13: =H13*Tableau1[[#This Row],[COURS 07/02]] -> 3772421.5 | J13: 0.847 | M13: =J13*D13 -> 0.0376915
B14: 28 | C14: CAPGEMINI | D14: 0.04 | E14: 173 | F14: 172.4 | G14: 185.15 | H14: =ROUNDDOWN(D14*$H$2/Tableau1[[#This Row],[COURS 27/01]],0) -> 18497 | I14: =H14*Tableau1[[#This Row],[COURS 07/02]] -> 3424719.6 | J14: 1.15 | M14: =J14*D14 -> 0.046
B15: 23 | C15: Virbac | D15: 0.0145 | E15: 281 | F15: 277.5 | G15: 292.5 | H15: =ROUNDDOWN(D15*$H$2/Tableau1[[#This Row],[COURS 27/01]],0) -> 4128 | I15: =H15*Tableau1[[#This Row],[COURS 07/02]] -> 1207440 | J15: 0.803 | M15: =J15*D15 -> 0.0116435
B16: 24 | C16: ESSILORLUXOTTICA | D16: 0.0145 | E16: 166.15 | F16: 167.25 | G16: 174.5 | H16: =ROUNDDOWN(D16*$H$2/Tableau1[[#This Row],[COURS 27/01]],0) -> 6981 | I16: =H16*Tableau1[[#This Row],[COURS 07/02]] -> 1218184.5 | J16: 0.912 | M16: =J16*D16 -> 0.013224
B17: 25 | C17: AUBAY | D17: 0.02 | E17: 49.85 | F17: 48 | G17: 49.95 | H17: =ROUNDDOWN(D17*$H$2/Tableau1[[#This Row],[COURS 27/01]],0) -> 32096 | I17: =H17*Tableau1[[#This Row],[COURS 07/02]] -> 1603195.2 | J17: 1.36 | M17: =J17*D17 -> 0.0272
B18: 14 | C18: STMicroelectronics | D18: 0.045 | E18: 43.69 | F18: 43.42 | G18: 45.155 | H18: =ROUNDDOWN(D18*$H$2/Tableau1[[#This Row],[COURS 27/01]],0) -> 82398 | I18: =H18*Tableau1[[#This Row],[COURS 07/02]] -> 3720681.7 | J18: 1.29 | M18: =J18*D18 -> 0.05805
B19: 7 | C19: SCHNEIDER ELECTRIC SE | D19: 0.05 | E19: 147.88 | F19: 147.14 | G19: 152.66 | H19: =ROUNDDOWN(D19*$H$2/Tableau1[[#This Row],[COURS 27/01]],0) -> 27048 | I19: =H19*Tableau1[[#This Row],[COURS 07/02]] -> 4129147.7 | J19: 1 | M19: =J19*D19 -> 0.05
B20: 21 | C20: COVIVIO | D20: 0.02 | E20: 63.15 | F20: 62.75 | G20: 65.1 | H20: =ROUNDDOWN(D20*$H$2/Tableau1[[#This Row],[COURS 27/01]],0) -> 25336 | I20: =H20*Tableau1[[#This Row],[COURS 07/02]] -> 1649373.6 | J20: 1.43 | M20: =J20*D20 -> 0.0286
B21: 16 | C21: PERNOD RICARD | D21: 0.05 | E21: 184.2 | F21: 186.3 | G21: 192.2 | H21: =ROUNDDOWN(D21*$H$2/Tableau1[[#This Row],[COURS 27/01]],0) -> 21715 | I21: =H21*Tableau1[[#This Row],[COURS 07/02]] -> 4173623 | J21: 0.43 | M21: =J21*D21 -> 0.0215
B22: 10 | C22: HERMES | D22: 0.05 | E22: 1697.5 | F22: 1.692,50 | G22: 1741.5 | H22: =ROUNDDOWN(D22*$H$2/Tableau1[[#This Row],[COURS 27/01]],0) -> 2356 | I22: =H22*Tableau1[[#This Row],[COURS 07/02]] -> 4102974 | J22: 0.657 | M22: =J22*D22 -> 0.03285 | O22: =100-99.52 -> 0.48
B23: 20 | C23: SAINT GOBAIN | D23: 0.02 | E23: 54.19 | F23: 53.27 | G23: 54.68 | H23: =ROUNDDOWN(D23*$H$2/Tableau1[[#This Row],[COURS 27/01]],0) -> 29525 | I23: =H23*Tableau1[[#This Row],[COURS 07/02]] -> 1614427 | J23: 1.36 | M23: =J23*D23 -> 0.0272
B24: 12 | C24: KERING | D24: 0.04 | E24: 557.7 | F24: 565.7 | G24: 579.5 | H24: =ROUNDDOWN(D24*$H$2/Tableau1[[#This Row],[COURS 27/01]],0) -> 5737 | I24: =H24*Tableau1[[#This Row],[COURS 07/02]] -> 3324591.5 | J24: 1.07 | M24: =J24*D24 -> 0.0428
B25: 3 | C25: LVMH | D25: 0.05 | E25: 801 | F25: 797.1 | G25: 812.6 | H25: =ROUNDDOWN(D25*$H$2/Tableau1[[#This Row],[COURS 27/01]],0) -> 4993 | I25: =H25*Tableau1[[#This Row],[COURS 07/02]] -> 4057311.8 | J25: 0.964 | M25: =J25*D25 -> 0.0482 | O25: =20470*G35 -> 1155940.9
B26: 2 | C26: AIRBUS | D26: 0.04 | E26: 116.62 | F26: 112.56 | G26: 114 | H26: =ROUNDDOWN(D26*$H$2/Tableau1[[#This Row],[COURS 27/01]],0) -> 27439 | I26: =H26*Tableau1[[#This Row],[COURS 07/02]] -> 3128046 | J26: 1.7 | M26: =J26*D26 -> 0.068
B27: 4 | C27: L'OREAL | D27: 0.05 | E27: 378.45 | F27: 378.55 | G27: 380.65 | H27: =ROUNDDOWN(D27*$H$2/Tableau1[[#This Row],[COURS 27/01]],0) -> 10569 | I27: =H27*Tableau1[[#This Row],[COURS 07/02]] -> 4023089.8 | J27: 0.604 | M27: =J27*D27 -> 0.0302
B28: 8 | C28: VINCI SA | D28: 0.02 | E28: 105.04 | F28: 104.14 | G28: 104.7 | H28: =ROUNDDOWN(D28*$H$2/Tableau1[[#This Row],[COURS 27/01]],0) -> 15232 | I28: =H28*Tableau1[[#This Row],[COURS 07/02]] -> 1594790.4 | J28: 0.953 | M28: =J28*D28 -> 0.01906
B29: 1 | C29: DANONE | D29: 0.028 | E29: 49.53 | F29: 50.25 | G29: 50.42 | H29: =ROUNDDOWN(D29*$H$2/Tableau1[[#This Row],[COURS 27/01]],0) -> 45225 | I29: =H29*Tableau1[[#This Row],[COURS 07/02]] -> 2280244.5 | J29: 0.49 | M29: =J29*D29 -> 0.01372
B30: 11 | C30: BOUYGUES | D30: 0.015 | E30: 30.25 | F30: 30.35 | G30: 30.36 | H30: =ROUNDDOWN(D30*$H$2/Tableau1[[#This Row],[COURS 27/01]],0) -> 39669 | I30: =H30*Tableau1[[#This Row],[COURS 07/02]] -> 1204350.8 | J30: 0.955 | M30: =J30*D30 -> 0.014325 | O30: =1.47+1.5 -> 2.97 | P30: =1.47+1.5+1 -> 3.97
B31: 13 | C31: SAFRAN | D31: 0.0345 | E31: 132.2 | F31: 131.36 | G31: 131.24 | H31: =ROUNDDOWN(D31*$H$2/Tableau1[[#This Row],[COURS 27/01]],0) -> 20877 | I31: =H31*Tableau1[[#This Row],[COURS 07/02]] -> 2739897.5 | J31: 1.33 | M31: =J31*D31 -> 0.045885
B32: 22 | C32: THALES | D32: 0.05 | E32: 121.3 | F32: 120.45 | G32: 118.75 | H32: =ROUNDDOWN(D32*$H$2/Tableau1[[#This Row],[COURS 27/01]],0) -> 32976 | I32: =H32*Tableau1[[#This Row],[COURS 07/02]] -> 3915900 | J32: 0.635 | M32: =J32*D32 -> 0.03175
B33: 18 | C33: BNP PARIBAS | D33: 0.015 | E33: 62.03 | F33: 62.66 | G33: 61.24 | H33: =ROUNDDOWN(D33*$H$2/Tableau1[[#This Row],[COURS 27/01]],0) -> 19345 | I33: =H33*Tableau1[[#This Row],[COURS 07/02]] -> 1184687.8 | J33: 1.73 | M33: =J33*D33 -> 0.02595 | P33: =1 -> 1
B34: 19 | C34: CARREFOUR | D34: 0.03 | E34: 17.51 | F34: 17.52 | G34: 17.1 | H34: =ROUNDDOWN(D34*$H$2/Tableau1[[#This Row],[COURS 27/01]],0) -> 137064 | I34: =H34*Tableau1[[#This Row],[COURS 07/02]] -> 2343794.4 | J34: 0.549 | M34: =J34*D34 -> 0.01647
B35: 5 | C35: TOTALEnergies SE | D35: 0.035 | E35: 58.62 | F35: 57.89 | G35: 56.47 | H35: =ROUNDDOWN(D35*$H$2/Tableau1[[#This Row],[COURS 27/01]],0) -> 47765 | I35: =H35*Tableau1[[#This Row],[COURS 07/02]] -> 2697289.5 | J35: 0.993 | M35: =J35*D35 -> 0.034755
B36: 6 | C36: AIR LIQUIDE SA | D36: 0.05 | E36: 148.26 | F36: 147.8 | G36: 144 | H36: =ROUNDDOWN(D36*$H$2/Tableau1[[#This Row],[COURS 27/01]],0) -> 26979 | I36: =H36*Tableau1[[#This Row],[COURS 07/02]] -> 3884976 | J36: 0.636 | M36: =J36*D36 -> 0.0318
B37: 9 | C37: SANOFI | D37: 0.05 | E37: 89.55 | F37: 89.73 | G37: 85.56 | H37: =ROUNDDOWN(D37*$H$2/Tableau1[[#This Row],[COURS 27/01]],0) -> 44667 | I37: =H37*Tableau1[[#This Row],[COURS 07/02]] -> 3821708.5 | J37: 0.416 | M37: =J37*D37 -> 0.0208 | P37: =8093*148.26 -> 1199868.2
B38: 29 | C38: RENAULT | D38: =0.0295 -> 0.0295 | E38: 39.33 | F38: 15.88 | G38: 39.33 | H38: =ROUNDDOWN(D38*$H$2/Tableau1[[#This Row],[COURS 27/01]],0) -> 60005 | I38: =H38*Tableau1[[#This Row],[COURS 07/02]] -> 2359996.6 | J38: 1.67 | M38: =J38*D38 -> 0.049265
B39: TOTAL | D39: =SUM(D10:D38) -> 1 | I39: =SUM(I10:I38) -> 81716639 | J39: Beta Pondéré | M39: =SUM(M10:M38) -> 0.9333595
B41: Obligations
B43: Libellé | C43: Taux Coupon | D43: Maturité | E43: Date Coupon | H43: Rendement | I43: Date achat | J43: Cours du 27/01 | K43: Cours du 31/01 | L43: Cours du 07/02 | M43: Pondération | N43: Nbre de titre | O43: Montant | P43: Performance
B44: OAT 10 ans | C44: 0.02 | D44: 48543 | E44: 45255 | H44: 0.02702 | I44: 44953 | J44: 100 | K44: 93.7 | L44: 93.73 | M44: 0.6 | N44: =ROUNDDOWN(M44*$H$3/J44,0) -> 60000 | O44: =N44*L44 -> 5623800 | P44: =(L44-K44)/K44 -> 0.00032017076
B45: OAT 5 ans | C45: 0.0075 | D45: 46898 | E45: 45071 | H45: 0.025388 | I45: 44953 | J45: 91.49 | K45: 90.72 | L45: 91.11 | M45: 0.4 | N45: =ROUNDDOWN(M45*$H$3/J45,0) -> 43720 | O45: =N45*L45 -> 3983329.2 | P45: =(L45-K45)/K45 -> 0.0042989418
...

Sheet 13.02
E1: Actif | I1: Montant
E2: Actions | I2: =100000000-I4-I5-I3 -> 80000000
E3: Obligations | I3: 10000000
E4: Monétaire | I4: =0.1*100000000 -> 10000000
B7: Actions ( avant arbitrage)
B9: NOMBRES | C9: TITRES | D9: PONDERATION | E9: COURS 27/01 | F9: COURS 31/01 | G9: COURS 07/02 | H9: COURS 13/02 | I9: Nbre d'actions | J9: VALEUR DU PORTEFEUILLE | K9: BETA | L9: Colonne1 | M9: Colonne2 | N9: Colonne3 | O9: Béta pondéré | P9: Performance
B10: 5 | C10: TOTALEnergies SE | D10: 0.035 | E10: 58.62 | F10: 57.89 | G10: 56.47 | H10: 59.34 | I10: =ROUNDDOWN(D10*$I$2/Tableau15[[#This Row],[COURS 27/01]],0) -> 47765 | J10: =I10*Tableau15[[#This Row],[COURS 13/02]] -> 2834375.1 | K10: 0.993 | O10: =K10*D10 -> 0.034755 | P10: =(Tableau15[[#This Row],[COURS 13/02]]-Tableau15[[#This Row],[COURS 07/02]])/Tableau15[[#This Row],[COURS 07/02]] -> 0.050823446
B11: 18 | C11: BNP PARIBAS | D11: 0.045 | E11: 62.03 | F11: 62.66 | G11: 61.24 | H11: 63.75 | I11: =ROUNDDOWN(D11*$I$2/Tableau15[[#This Row],[COURS 27/01]],0) -> 58036 | J11: =I11*Tableau15[[#This Row],[COURS 13/02]] -> 3699795 | K11: 1.73 | O11: =K11*D11 -> 0.07785 | P11: =(Tableau15[[#This Row],[COURS 13/02]]-Tableau15[[#This Row],[COURS 07/02]])/Tableau15[[#This Row],[COURS 07/02]] -> 0.040986283
B12: 29 | C12: RENAULT | D12: =4% -> 0.04 | E12: 39.33 | F12: 15.88 | G12: 39.33 | H12: 40.85 | I12: =ROUNDDOWN(D12*$I$2/Tableau15[[#This Row],[COURS 27/01]],0) -> 81362 | J12: =I12*Tableau15[[#This Row],[COURS 13/02]] -> 3323637.7 | K12: 1.67 | O12: =K12*D12 -> 0.0668 | P12: =(Tableau15[[#This Row],[COURS 13/02]]-Tableau15[[#This Row],[COURS 07/02]])/Tableau15[[#This Row],[COURS 07/02]] -> 0.038647343
B13: 9 | C13: SANOFI | D13: 0.03 | E13: 89.55 | F13: 89.73 | G13: 85.56 | H13: 88.52 | I13: =ROUNDDOWN(D13*$I$2/Tableau15[[#This Row],[COURS 27/01]],0) -> 26800 | J13: =I13*Tableau15[[#This Row],[COURS 13/02]] -> 2372336 | K13: 0.416 | O13: =K13*D13 -> 0.01248 | P13: =(Tableau15[[#This Row],[COURS 13/02]]-Tableau15[[#This Row],[COURS 07/02]])/Tableau15[[#This Row],[COURS 07/02]] -> 0.034595605
B14: 22 | C14: THALES | D14: 0.05 | E14: 121.3 | F14: 120.45 | G14: 118.75 | H14: 122.45 | I14: =ROUNDDOWN(D14*$I$2/Tableau15[[#This Row],[COURS 27/01]],0) -> 32976 | J14: =I14*Tableau15[[#This Row],[COURS 13/02]] -> 4037911.2 | K14: 0.635 | O14: =K14*D14 -> 0.03175 | P14: =(Tableau15[[#This Row],[COURS 13/02]]-Tableau15[[#This Row],[COURS 07/02]])/Tableau15[[#This Row],[COURS 07/02]] -> 0.031157895
B15: 25 | C15: AUBAY | D15: 0.02 | E15: 49.85 | F15: 48 | G15: 49.95 | H15: 51.3 | I15: =ROUNDDOWN(D15*$I$2/Tableau15[[#This Row],[COURS 27/01]],0) -> 32096 | J15: =I15*Tableau15[[#This Row],[COURS 13/02]] -> 1646524.8 | K15: 1.36 | O15: =K15*D15 -> 0.0272 | P15: =(Tableau15[[#This Row],[COURS 13/02]]-Tableau15[[#This Row],[COURS 07/02]])/Tableau15[[#This Row],[COURS 07/02]] -> 0.027027027
B16: 26 | C16: CATANA GROUPE | D16: 0.01 | E16: 6.48 | F16: 6.5 | G16: 7 | H16: 7.13 | I16: =ROUNDDOWN(D16*$I$2/Tableau15[[#This Row],[COURS 27/01]],0) -> 123456 | J16: =I16*Tableau15[[#This Row],[COURS 13/02]] -> 880241.28 | K16: 1.7 | O16: =K16*D16 -> 0.017 | P16: =(Tableau15[[#This Row],[COURS 13/02]]-Tableau15[[#This Row],[COURS 07/02]])/Tableau15[[#This Row],[COURS 07/02]] -> 0.018571429
B17: 27 | C17: PUBLICIS GROUPE | D17: 0.05 | E17: 64.46 | F17: 65.04 | G17: 73.46 | H17: 74.18 | I17: =ROUNDDOWN(D17*$I$2/Tableau15[[#This Row],[COURS 27/01]],0) -> 62053 | J17: =I17*Tableau15[[#This Row],[COURS 13/02]] -> 4603091.5 | K17: 0.913 | O17: =K17*D17 -> 0.04565 | P17: =(Tableau15[[#This Row],[COURS 13/02]]-Tableau15[[#This Row],[COURS 07/02]])/Tableau15[[#This Row],[COURS 07/02]] -> 0.0098012524
B18: 8 | C18: VINCI SA | D18: 0.03 | E18: 105.04 | F18: 104.14 | G18: 104.7 | H18: 105.16 | I18: =ROUNDDOWN(D18*$I$2/Tableau15[[#This Row],[COURS 27/01]],0) -> 22848 | J18: =I18*Tableau15[[#This Row],[COURS 13/02]] -> 2402695.7 | K18: 0.953 | O18: =K18*D18 -> 0.02859 | P18: =(Tableau15[[#This Row],[COURS 13/02]]-Tableau15[[#This Row],[COURS 07/02]])/Tableau15[[#This Row],[COURS 07/02]] -> 0.0043935053
B19: 2 | C19: AIRBUS | D19: 0.04 | E19: 116.62 | F19: 112.56 | G19: 114 | H19: 114.3 | I19: =ROUNDDOWN(D19*$I$2/Tableau15[[#This Row],[COURS 27/01]],0) -> 27439 | J19: =I19*Tableau15[[#This Row],[COURS 13/02]] -> 3136277.7 | K19: 1.7 | O19: =K19*D19 -> 0.068 | P19: =(Tableau15[[#This Row],[COURS 13/02]]-Tableau15[[#This Row],[COURS 07/02]])/Tableau15[[#This Row],[COURS 07/02]] -> 0.0026315789
B20: 14 | C20: STMicroelectronics | D20: 0.045 | E20: 43.69 | F20: 43.42 | G20: 45.155 | H20: 45.245 | I20: =ROUNDDOWN(D20*$I$2/Tableau15[[#This Row],[COURS 27/01]],0) -> 82398 | J20: =I20*Tableau15[[#This Row],[COURS 13/02]] -> 3728097.5 | K20: 1.29 | O20: =K20*D20 -> 0.05805 | P20: =(Tableau15[[#This Row],[COURS 13/02]]-Tableau15[[#This Row],[COURS 07/02]])/Tableau15[[#This Row],[COURS 07/02]] -> 0.0019931348
B21: 1 | C21: DANONE | D21: 0.028 | E21: 49.53 | F21: 50.25 | G21: 50.42 | H21: 50.34 | I21: =ROUNDDOWN(D21*$I$2/Tableau15[[#This Row],[COURS 27/01]],0) -> 45225 | J21: =I21*Tableau15[[#This Row],[COURS 13/02]] -> 2276626.5 | K21: 0.49 | O21: =K21*D21 -> 0.01372 | P21: =(Tableau15[[#This Row],[COURS 13/02]]-Tableau15[[#This Row],[COURS 07/02]])/Tableau15[[#This Row],[COURS 07/02]] -> -0.001586672
B22: 4 | C22: L'OREAL | D22: 0.05 | E22: 378.45 | F22: 378.55 | G22: 380.65 | H22: 380 | I22: =ROUNDDOWN(D22*$I$2/Tableau15[[#This Row],[COURS 27/01]],0) -> 10569 | J22: =I22*Tableau15[[#This Row],[COURS 13/02]] -> 4016220 | K22: 0.604 | O22: =K22*D22 -> 0.0302 | P22: =(Tableau15[[#This Row],[COURS 13/02]]-Tableau15[[#This Row],[COURS 07/02]])/Tableau15[[#This Row],[COURS 07/02]] -> -0.0017076054 | Q22: =100-99.52 -> 0.48
B23: 13 | C23: SAFRAN | D23: 0.0345 | E23: 132.2 | F23: 131.36 | G23: 131.24 | H23: 130.54 | I23: =ROUNDDOWN(D23*$I$2/Tableau15[[#This Row],[COURS 27/01]],0) -> 20877 | J23: =I23*Tableau15[[#This Row],[COURS 13/02]] -> 2725283.6 | K23: 1.33 | O23: =K23*D23 -> 0.045885 | P23: =(Tableau15[[#This Row],[COURS 13/02]]-Tableau15[[#This Row],[COURS 07/02]])/Tableau15[[#This Row],[COURS 07/02]] -> -0.0053337397
B24: 6 | C24: AIR LIQUIDE SA | D24: 0.035 | E24: 148.26 | F24: 147.8 | G24: 144 | H24: 142.9 | I24: =ROUNDDOWN(D24*$I$2/Tableau15[[#This Row],[COURS 27/01]],0) -> 18885 | J24: =I24*Tableau15[[#This Row],[COURS 13/02]] -> 2698666.5 | K24: 0.636 | O24: =K24*D24 -> 0.02226 | P24: =(Tableau15[[#This Row],[COURS 13/02]]-Tableau15[[#This Row],[COURS 07/02]])/Tableau15[[#This Row],[COURS 07/02]] -> -0.0076388889
B25: 11 | C25: BOUYGUES | D25: 0.015 | E25: 30.25 | F25: 30.35 | G25: 30.36 | H25: 30.126 | I25: =ROUNDDOWN(D25*$I$2/Tableau15[[#This Row],[COURS 27/01]],0) -> 39669 | J25: =I25*Tableau15[[#This Row],[COURS 13/02]] -> 1195068.3 | K25: 0.955 | O25: =K25*D25 -> 0.014325 | P25: =(Tableau15[[#This Row],[COURS 13/02]]-Tableau15[[#This Row],[COURS 07/02]])/Tableau15[[#This Row],[COURS 07/02]] -> -0.0077075099 | Q25: =20470*G35 -> 11862365
B26: 23 | C26: Virbac | D26: 0.0135 | E26: 281 | F26: 277.5 | G26: 292.5 | H26: 289 | I26: =ROUNDDOWN(D26*$I$2/Tableau15[[#This Row],[COURS 27/01]],0) -> 3843 | J26: =I26*Tableau15[[#This Row],[COURS 13/02]] -> 1110627 | K26: 0.803 | O26: =K26*D26 -> 0.0108405 | P26: =(Tableau15[[#This Row],[COURS 13/02]]-Tableau15[[#This Row],[COURS 07/02]])/Tableau15[[#This Row],[COURS 07/02]] -> -0.011965812
B27: 28 | C27: CAPGEMINI | D27: 0.04 | E27: 173 | F27: 172.4 | G27: 185.15 | H27: 182.9 | I27: =ROUNDDOWN(D27*$I$2/Tableau15[[#This Row],[COURS 27/01]],0) -> 18497 | J27: =I27*Tableau15[[#This Row],[COURS 13/02]] -> 3383101.3 | K27: 1.15 | O27: =K27*D27 -> 0.046 | P27: =(Tableau15[[#This Row],[COURS 13/02]]-Tableau15[[#This Row],[COURS 07/02]])/Tableau15[[#This Row],[COURS 07/02]] -> -0.012152309
B28: 3 | C28: LVMH | D28: 0.05 | E28: 801 | F28: 797.1 | G28: 812.6 | H28: 800.5 | I28: =ROUNDDOWN(D28*$I$2/Tableau15[[#This Row],[COURS 27/01]],0) -> 4993 | J28: =I28*Tableau15[[#This Row],[COURS 13/02]] -> 3996896.5 | K28: 0.964 | O28: =K28*D28 -> 0.0482 | P28: =(Tableau15[[#This Row],[COURS 13/02]]-Tableau15[[#This Row],[COURS 07/02]])/Tableau15[[#This Row],[COURS 07/02]] -> -0.014890475
B29: 21 | C29: COVIVIO | D29: 0.02 | E29: 63.15 | F29: 62.75 | G29: 65.1 | H29: 64.1 | I29: =ROUNDDOWN(D29*$I$2/Tableau15[[#This Row],[COURS 27/01]],0) -> 25336 | J29: =I29*Tableau15[[#This Row],[COURS 13/02]] -> 1624037.6 | K29: 1.43 | O29: =K29*D29 -> 0.0286 | P29: =(Tableau15[[#This Row],[COURS 13/02]]-Tableau15[[#This Row],[COURS 07/02]])/Tableau15[[#This Row],[COURS 07/02]] -> -0.015360983
B30: 7 | C30: SCHNEIDER ELECTRIC SE | D30: 0.05 | E30: 147.88 | F30: 147.14 | G30: 152.66 | H30: 150 | I30: =ROUNDDOWN(D30*$I$2/Tableau15[[#This Row],[COURS 27/01]],0) -> 27048 | J30: =I30*Tableau15[[#This Row],[COURS 13/02]] -> 4057200 | K30: 1 | O30: =K30*D30 -> 0.05 | P30: =(Tableau15[[#This Row],[COURS 13/02]]-Tableau15[[#This Row],[COURS 07/02]])/Tableau15[[#This Row],[COURS 07/02]] -> -0.017424342 | Q30: =1.47+1.5 -> 2.97 | R30: =1.47+1.5+1 -> 3.97
B31: 15 | C31: NEOEN | D31: 0.0445 | E31: 34.69 | F31: 34.22 | G31: 36.76 | H31: 35.9 | I31: =ROUNDDOWN(D31*$I$2/Tableau15[[#This Row],[COURS 27/01]],0) -> 102623 | J31: =I31*Tableau15[[#This Row],[COURS 13/02]] -> 3684165.7 | K31: 0.847 | O31: =K31*D31 -> 0.0376915 | P31: =(Tableau15[[#This Row],[COURS 13/02]]-Tableau15[[#This Row],[COURS 07/02]])/Tableau15[[#This Row],[COURS 07/02]] -> -0.023394995
B32: 16 | C32: PERNOD RICARD | D32: 0.03 | E32: 184.2 | F32: 186.3 | G32: 192.2 | H32: 187.35 | I32: =ROUNDDOWN(D32*$I$2/Tableau15[[#This Row],[COURS 27/01]],0) -> 13029 | J32: =I32*Tableau15[[#This Row],[COURS 13/02]] -> 2440983.1 | K32: 0.43 | O32: =K32*D32 -> 0.0129 | P32: =(Tableau15[[#This Row],[COURS 13/02]]-Tableau15[[#This Row],[COURS 07/02]])/Tableau15[[#This Row],[COURS 07/02]] -> -0.025234131
B33: 17 | C33: DASSAULT | D33: 0.04 | E33: 33.69 | F33: 34.06 | G33: 38.05 | H33: 37.01 | I33: =ROUNDDOWN(D33*$I$2/Tableau15[[#This Row],[COURS 27/01]],0) -> 94983 | J33: =I33*Tableau15[[#This Row],[COURS 13/02]] -> 3515320.8 | K33: 0.689 | O33: =K33*D33 -> 0.02756 | P33: =(Tableau15[[#This Row],[COURS 13/02]]-Tableau15[[#This Row],[COURS 07/02]])/Tableau15[[#This Row],[COURS 07/02]] -> -0.027332457 | R33: =1 -> 1
B34: 24 | C34: ESSILORLUXOTTICA | D34: 0.0145 | E34: 166.15 | F34: 167.25 | G34: 174.5 | H34: 168.6 | I34: =ROUNDDOWN(D34*$I$2/Tableau15[[#This Row],[COURS 27/01]],0) -> 6981 | J34: =I34*Tableau15[[#This Row],[COURS 13/02]] -> 1176996.6 | K34: 0.912 | O34: =K34*D34 -> 0.013224 | P34: =(Tableau15[[#This Row],[COURS 13/02]]-Tableau15[[#This Row],[COURS 07/02]])/Tableau15[[#This Row],[COURS 07/02]] -> -0.033810888
B35: 12 | C35: KERING | D35: 0.05 | E35: 557.7 | F35: 565.7 | G35: 579.5 | H35: 559.5 | I35: =ROUNDDOWN(D35*$I$2/Tableau15[[#This Row],[COURS 27/01]],0) -> 7172 | J35: =I35*Tableau15[[#This Row],[COURS 13/02]] -> 4012734 | K35: 1.07 | O35: =K35*D35 -> 0.0535 | P35: =(Tableau15[[#This Row],[COURS 13/02]]-Tableau15[[#This Row],[COURS 07/02]])/Tableau15[[#This Row],[COURS 07/02]] -> -0.034512511
B36: 10 | C36: HERMES | D36: 0.05 | E36: 1697.5 | F36: 1.692,50 | G36: 1741.5 | H36: 1680 | I36: =ROUNDDOWN(D36*$I$2/Tableau15[[#This Row],[COURS 27/01]],0) -> 2356 | J36: =I36*Tableau15[[#This Row],[COURS 13/02]] -> 3958080 | K36: 0.657 | O36: =K36*D36 -> 0.03285 | P36: =(Tableau15[[#This Row],[COURS 13/02]]-Tableau15[[#This Row],[COURS 07/02]])/Tableau15[[#This Row],[COURS 07/02]] -> -0.035314384
B37: 20 | C37: SAINT GOBAIN | D37: 0.02 | E37: 54.19 | F37: 53.27 | G37: 54.68 | H37: 52.67 | I37: =ROUNDDOWN(D37*$I$2/Tableau15[[#This Row],[COURS 27/01]],0) -> 29525 | J37: =I37*Tableau15[[#This Row],[COURS 13/02]] -> 1555081.8 | K37: 1.36 | O37: =K37*D37 -> 0.0272 | P37: =(Tableau15[[#This Row],[COURS 13/02]]-Tableau15[[#This Row],[COURS 07/02]])/Tableau15[[#This Row],[COURS 07/02]] -> -0.036759327 | R37: =8093*148.26 -> 1199868.2
B38: 19 | C38: CARREFOUR | D38: 0.02 | E38: 17.51 | F38: 17.52 | G38: 17.1 | H38: 16.375 | I38: =ROUNDDOWN(D38*$I$2/Tableau15[[#This Row],[COURS 27/01]],0) -> 91376 | J38: =I38*Tableau15[[#This Row],[COURS 13/02]] -> 1496282 | K38: 0.549 | O38: =K38*D38 -> 0.01098 | P38: =(Tableau15[[#This Row],[COURS 13/02]]-Tableau15[[#This Row],[COURS 07/02]])/Tableau15[[#This Row],[COURS 07/02]] -> -0.042397661
B39: TOTAL | D39: =SUM(D10:D38) -> 1 | J39: =SUM(J10:J38) -> 81588355 | K39: Beta Pondéré | O39: =SUM(O10:O38) -> 0.994061 | P39: =SUM(Tableau15[Performance]) -> -0.093896191
B41: Obligations
B43: Libellé | C43: Taux Coupon | D43: Maturité | E43: Date Coupon | I43: Rendement | J43: Date achat | K43: Cours du 27/01 | L43: Cours du 31/01 | M43: Cours du 07/02 | N43: Cours 13/02 | O43: Pondération | P43: Nbre de titre | Q43: Montant | R43: Performance
B44: OAT 10 ans | C44: 0.02 | D44: 48543 | E44: 45255 | I44: 0.02702 | J44: 44953 | K44: 100 | L44: 93.7 | M44: 93.73 | N44: 93.08 | O44: 0.6 | P44: =ROUNDDOWN(O44*$I$3/K44,0) -> 60000 | Q44: =P44*N44 -> 5584800 | R44: =(N44-M44)/M44 -> -0.0069348128
B45: OAT 5 ans | C45: 0.0075 | D45: 46898 | E45: 45071 | I45: 0.025388 | J45: 44953 | K45: 91.49 | L45: 90.72 | M45: 91.11 | N45: 90.65 | O45: 0.4 | P45: =ROUNDDOWN(O45*$I$3/K45,0) -> 43720 | Q45: =P45*N45 -> 3963218 | R45: =(M45-L45)/L45 -> 0.0042989418
...

Sheet 07.03
E1: Actif | J1: Montant
E2: Actions | J2: =100000000-J4-J5-J3 -> 80000000
E3: Obligations | J3: 10000000
E4: Monétaire | J4: =0.1*100000000 -> 10000000
B7: Actions ( avant arbitrage)
B9: NOMBRES | C9: TITRES | D9: PONDERATION | E9: COURS 27/01 | F9: COURS 31/01 | G9: COURS 07/02 | H9: COURS 13/02 | I9: COURS 07/03 | J9: Nbre d'actions | K9: VALEUR DU PORTEFEUILLE | L9: BETA | M9: Colonne1 | N9: Colonne2 | O9: Colonne3 | P9: Colonne4 | Q9: Béta pondéré | R9: Performance
B10: 9 | C10: SANOFI | D10: 0.03 | E10: 89.55 | F10: 89.73 | G10: 85.56 | H10: 88.52 | I10: 89.2 | J10: =ROUNDDOWN(D10*$J$2/Tableau156[[#This Row],[COURS 27/01]],0) -> 26800 | K10: =J10*Tableau156[[#This Row],[COURS 07/03]] -> 2390560 | L10: 0.416 | Q10: =L10*D10 -> 0.01248 | R10: =(Tableau156[[#This Row],[COURS 07/03]]-Tableau156[[#This Row],[COURS 13/02]])/Tableau156[[#This Row],[COURS 13/02]] -> 0.0076818798
B11: 16 | C11: PERNOD RICARD | D11: 0.03 | E11: 184.2 | F11: 186.3 | G11: 192.2 | H11: 187.35 | I11: 200.3 | J11: =ROUNDDOWN(D11*$J$2/Tableau156[[#This Row],[COURS 27/01]],0) -> 13029 | K11: =J11*Tableau156[[#This Row],[COURS 07/03]] -> 2609708.7 | L11: 0.43 | Q11: =L11*D11 -> 0.0129 | R11: =(Tableau156[[#This Row],[COURS 07/03]]-Tableau156[[#This Row],[COURS 13/02]])/Tableau156[[#This Row],[COURS 13/02]] -> 0.069121964
B12: 1 | C12: DANONE | D12: 0.028 | E12: 49.53 | F12: 50.25 | G12: 50.42 | H12: 50.34 | I12: 53.39 | J12: =ROUNDDOWN(D12*$J$2/Tableau156[[#This Row],[COURS 27/01]],0) -> 45225 | K12: =J12*Tableau156[[#This Row],[COURS 07/03]] -> 2414562.8 | L12: 0.49 | Q12: =L12*D12 -> 0.01372 | R12: =(Tableau156[[#This Row],[COURS 07/03]]-Tableau156[[#This Row],[COURS 13/02]])/Tableau156[[#This Row],[COURS 13/02]] -> 0.060588002
B13: 19 | C13: CARREFOUR | D13: 0.02 | E13: 17.51 | F13: 17.52 | G13: 17.1 | H13: 16.375 | I13: 17.94 | J13: =ROUNDDOWN(D13*$J$2/Tableau156[[#This Row],[COURS 27/01]],0) -> 91376 | K13: =J13*Tableau156[[#This Row],[COURS 07/03]] -> 1639285.4 | L13: 0.549 | Q13: =L13*D13 -> 0.01098 | R13: =(Tableau156[[#This Row],[COURS 07/03]]-Tableau156[[#This Row],[COURS 13/02]])/Tableau156[[#This Row],[COURS 13/02]] -> 0.095572519
B14: 4 | C14: L'OREAL | D14: 0.05 | E14: 378.45 | F14: 378.55 | G14: 380.65 | H14: 380 | I14: 376.15 | J14: =ROUNDDOWN(D14*$J$2/Tableau156[[#This Row],[COURS 27/01]],0) -> 10569 | K14: =J14*Tableau156[[#This Row],[COURS 07/03]] -> 3975529.3 | L14: 0.604 | Q14: =L14*D14 -> 0.0302 | R14: =(Tableau156[[#This Row],[COURS 07/03]]-Tableau156[[#This Row],[COURS 13/02]])/Tableau156[[#This Row],[COURS 13/02]] -> -0.010131579
B15: 22 | C15: THALES | D15: 0.05 | E15: 121.3 | F15: 120.45 | G15: 118.75 | H15: 122.45 | I15: 132.2 | J15: =ROUNDDOWN(D15*$J$2/Tableau156[[#This Row],[COURS 27/01]],0) -> 32976 | K15: =J15*Tableau156[[#This Row],[COURS 07/03]] -> 4359427.2 | L15: 0.635 | Q15: =L15*D15 -> 0.03175 | R15: =(Tableau156[[#This Row],[COURS 07/03]]-Tableau156[[#This Row],[COURS 13/02]])/Tableau156[[#This Row],[COURS 13/02]] -> 0.079624336
B16: 6 | C16: AIR LIQUIDE SA | D16: 0.035 | E16: 148.26 | F16: 147.8 | G16: 144 | H16: 142.9 | I16: 148.36 | J16: =ROUNDDOWN(D16*$J$2/Tableau156[[#This Row],[COURS 27/01]],0) -> 18885 | K16: =J16*Tableau156[[#This Row],[COURS 07/03]] -> 2801778.6 | L16: 0.636 | Q16: =L16*D16 -> 0.02226 | R16: =(Tableau156[[#This Row],[COURS 07/03]]-Tableau156[[#This Row],[COURS 13/02]])/Tableau156[[#This Row],[COURS 13/02]] -> 0.038208537
B17: 10 | C17: HERMES | D17: 0.05 | E17: 1697.5 | F17: 1.692,50 | G17: 1741.5 | H17: 1680 | I17: 1741 | J17: =ROUNDDOWN(D17*$J$2/Tableau156[[#This Row],[COURS 27/01]],0) -> 2356 | K17: =J17*Tableau156[[#This Row],[COURS 07/03]] -> 4101796 | L17: 0.657 | Q17: =L17*D17 -> 0.03285 | R17: =(Tableau156[[#This Row],[COURS 07/03]]-Tableau156[[#This Row],[COURS 13/02]])/Tableau156[[#This Row],[COURS 13/02]] -> 0.036309524
B18: 17 | C18: DASSAULT | D18: 0.04 | E18: 33.69 | F18: 34.06 | G18: 38.05 | H18: 37.01 | I18: 37 | J18: =ROUNDDOWN(D18*$J$2/Tableau156[[#This Row],[COURS 27/01]],0) -> 94983 | K18: =J18*Tableau156[[#This Row],[COURS 07/03]] -> 3514371 | L18: 0.689 | Q18: =L18*D18 -> 0.02756 | R18: =(Tableau156[[#This Row],[COURS 07/03]]-Tableau156[[#This Row],[COURS 13/02]])/Tableau156[[#This Row],[COURS 13/02]] -> -0.00027019724
B19: 23 | C19: Virbac | D19: 0.0135 | E19: 281 | F19: 277.5 | G19: 292.5 | H19: 289 | I19: 283 | J19: =ROUNDDOWN(D19*$J$2/Tableau156[[#This Row],[COURS 27/01]],0) -> 3843 | K19: =J19*Tableau156[[#This Row],[COURS 07/03]] -> 1087569 | L19: 0.803 | Q19: =L19*D19 -> 0.0108405 | R19: =(Tableau156[[#This Row],[COURS 07/03]]-Tableau156[[#This Row],[COURS 13/02]])/Tableau156[[#This Row],[COURS 13/02]] -> -0.020761246
B20: 15 | C20: NEOEN | D20: 0.0445 | E20: 34.69 | F20: 34.22 | G20: 36.76 | H20: 35.9 | I20: 29.75 | J20: =ROUNDDOWN(D20*$J$2/Tableau156[[#This Row],[COURS 27/01]],0) -> 102623 | K20: =J20*Tableau156[[#This Row],[COURS 07/03]] -> 3053034.2 | L20: 0.847 | Q20: =L20*D20 -> 0.0376915 | R20: =(Tableau156[[#This Row],[COURS 07/03]]-Tableau156[[#This Row],[COURS 13/02]])/Tableau156[[#This Row],[COURS 13/02]] -> -0.17130919
B21: 24 | C21: ESSILORLUXOTTICA | D21: 0.0145 | E21: 166.15 | F21: 167.25 | G21: 174.5 | H21: 168.6 | I21: 165.35 | J21: =ROUNDDOWN(D21*$J$2/Tableau156[[#This Row],[COURS 27/01]],0) -> 6981 | K21: =J21*Tableau156[[#This Row],[COURS 07/03]] -> 1154308.3 | L21: 0.912 | Q21: =L21*D21 -> 0.013224 | R21: =(Tableau156[[#This Row],[COURS 07/03]]-Tableau156[[#This Row],[COURS 13/02]])/Tableau156[[#This Row],[COURS 13/02]] -> -0.019276394
B22: 27 | C22: PUBLICIS GROUPE | D22: 0.05 | E22: 64.46 | F22: 65.04 | G22: 73.46 | H22: 74.18 | I22: 76.94 | J22: =ROUNDDOWN(D22*$J$2/Tableau156[[#This Row],[COURS 27/01]],0) -> 62053 | K22: =J22*Tableau156[[#This Row],[COURS 07/03]] -> 4774357.8 | L22: 0.913 | Q22: =L22*D22 -> 0.04565 | R22: =(Tableau156[[#This Row],[COURS 07/03]]-Tableau156[[#This Row],[COURS 13/02]])/Tableau156[[#This Row],[COURS 13/02]] -> 0.037206794 | S22: =100-99.52 -> 0.48
B23: 8 | C23: VINCI SA | D23: 0.03 | E23: 105.04 | F23: 104.14 | G23: 104.7 | H23: 105.16 | I23: 108.9 | J23: =ROUNDDOWN(D23*$J$2/Tableau156[[#This Row],[COURS 27/01]],0) -> 22848 | K23: =J23*Tableau156[[#This Row],[COURS 07/03]] -> 2488147.2 | L23: 0.953 | Q23: =L23*D23 -> 0.02859 | R23: =(Tableau156[[#This Row],[COURS 07/03]]-Tableau156[[#This Row],[COURS 13/02]])/Tableau156[[#This Row],[COURS 13/02]] -> 0.035564854
B24: 11 | C24: BOUYGUES | D24: 0.015 | E24: 30.25 | F24: 30.35 | G24: 30.36 | H24: 30.126 | I24: 32.69 | J24: =ROUNDDOWN(D24*$J$2/Tableau156[[#This Row],[COURS 27/01]],0) -> 39669 | K24: =J24*Tableau156[[#This Row],[COURS 07/03]] -> 1296779.6 | L24: 0.955 | Q24: =L24*D24 -> 0.014325 | R24: =(Tableau156[[#This Row],[COURS 07/03]]-Tableau156[[#This Row],[COURS 13/02]])/Tableau156[[#This Row],[COURS 13/02]] -> 0.085109208
B25: 3 | C25: LVMH | D25: 0.05 | E25: 801 | F25: 797.1 | G25: 812.6 | H25: 800.5 | I25: 816.5 | J25: =ROUNDDOWN(D25*$J$2/Tableau156[[#This Row],[COURS 27/01]],0) -> 4993 | K25: =J25*Tableau156[[#This Row],[COURS 07/03]] -> 4076784.5 | L25: 0.964 | Q25: =L25*D25 -> 0.0482 | R25: =(Tableau156[[#This Row],[COURS 07/03]]-Tableau156[[#This Row],[COURS 13/02]])/Tableau156[[#This Row],[COURS 13/02]] -> 0.019987508 | S25: =20470*G35 -> 805085.1
B26: 5 | C26: TOTALEnergies SE | D26: 0.035 | E26: 58.62 | F26: 57.89 | G26: 56.47 | H26: 59.34 | I26: 59.55 | J26: =ROUNDDOWN(D26*$J$2/Tableau156[[#This Row],[COURS 27/01]],0) -> 47765 | K26: =J26*Tableau156[[#This Row],[COURS 07/03]] -> 2844405.8 | L26: 0.993 | Q26: =L26*D26 -> 0.034755 | R26: =(Tableau156[[#This Row],[COURS 07/03]]-Tableau156[[#This Row],[COURS 13/02]])/Tableau156[[#This Row],[COURS 13/02]] -> 0.0035389282
B27: 7 | C27: SCHNEIDER ELECTRIC SE | D27: 0.05 | E27: 147.88 | F27: 147.14 | G27: 152.66 | H27: 150 | I27: 155.5 | J27: =ROUNDDOWN(D27*$J$2/Tableau156[[#This Row],[COURS 27/01]],0) -> 27048 | K27: =J27*Tableau156[[#This Row],[COURS 07/03]] -> 4205964 | L27: 1 | Q27: =L27*D27 -> 0.05 | R27: =(Tableau156[[#This Row],[COURS 07/03]]-Tableau156[[#This Row],[COURS 13/02]])/Tableau156[[#This Row],[COURS 13/02]] -> 0.036666667
B28: 12 | C28: KERING | D28: 0.05 | E28: 557.7 | F28: 565.7 | G28: 579.5 | H28: 559.5 | I28: 574.1 | J28: =ROUNDDOWN(D28*$J$2/Tableau156[[#This Row],[COURS 27/01]],0) -> 7172 | K28: =J28*Tableau156[[#This Row],[COURS 07/03]] -> 4117445.2 | L28: 1.07 | Q28: =L28*D28 -> 0.0535 | R28: =(Tableau156[[#This Row],[COURS 07/03]]-Tableau156[[#This Row],[COURS 13/02]])/Tableau156[[#This Row],[COURS 13/02]] -> 0.026094727
B29: 28 | C29: CAPGEMINI | D29: 0.04 | E29: 173 | F29: 172.4 | G29: 185.15 | H29: 182.9 | I29: 180.1 | J29: =ROUNDDOWN(D29*$J$2/Tableau156[[#This Row],[COURS 27/01]],0) -> 18497 | K29: =J29*Tableau156[[#This Row],[COURS 07/03]] -> 3331309.7 | L29: 1.15 | Q29: =L29*D29 -> 0.046 | R29: =(Tableau156[[#This Row],[COURS 07/03]]-Tableau156[[#This Row],[COURS 13/02]])/Tableau156[[#This Row],[COURS 13/02]] -> -0.015308912
B30: 14 | C30: STMicroelectronics | D30: 0.045 | E30: 43.69 | F30: 43.42 | G30: 45.155 | H30: 45.245 | I30: 45.41 | J30: =ROUNDDOWN(D30*$J$2/Tableau156[[#This Row],[COURS 27/01]],0) -> 82398 | K30: =J30*Tableau156[[#This Row],[COURS 07/03]] -> 3741693.2 | L30: 1.29 | Q30: =L30*D30 -> 0.05805 | R30: =(Tableau156[[#This Row],[COURS 07/03]]-Tableau156[[#This Row],[COURS 13/02]])/Tableau156[[#This Row],[COURS 13/02]] -> 0.0036468118 | S30: =1.47+1.5 -> 2.97 | T30: =1.47+1.5+1 -> 3.97
B31: 13 | C31: SAFRAN | D31: 0.0345 | E31: 132.2 | F31: 131.36 | G31: 131.24 | H31: 130.54 | I31: 136.16 | J31: =ROUNDDOWN(D31*$J$2/Tableau156[[#This Row],[COURS 27/01]],0) -> 20877 | K31: =J31*Tableau156[[#This Row],[COURS 07/03]] -> 2842612.3 | L31: 1.33 | Q31: =L31*D31 -> 0.045885 | R31: =(Tableau156[[#This Row],[COURS 07/03]]-Tableau156[[#This Row],[COURS 13/02]])/Tableau156[[#This Row],[COURS 13/02]] -> 0.043051938
B32: 20 | C32: SAINT GOBAIN | D32: 0.02 | E32: 54.19 | F32: 53.27 | G32: 54.68 | H32: 52.67 | I32: 57.46 | J32: =ROUNDDOWN(D32*$J$2/Tableau156[[#This Row],[COURS 27/01]],0) -> 29525 | K32: =J32*Tableau156[[#This Row],[COURS 07/03]] -> 1696506.5 | L32: 1.36 | Q32: =L32*D32 -> 0.0272 | R32: =(Tableau156[[#This Row],[COURS 07/03]]-Tableau156[[#This Row],[COURS 13/02]])/Tableau156[[#This Row],[COURS 13/02]] -> 0.090943611
B33: 25 | C33: AUBAY | D33: 0.02 | E33: 49.85 | F33: 48 | G33: 49.95 | H33: 51.3 | I33: 48.7 | J33: =ROUNDDOWN(D33*$J$2/Tableau156[[#This Row],[COURS 27/01]],0) -> 32096 | K33: =J33*Tableau156[[#This Row],[COURS 07/03]] -> 1563075.2 | L33: 1.36 | Q33: =L33*D33 -> 0.0272 | R33: =(Tableau156[[#This Row],[COURS 07/03]]-Tableau156[[#This Row],[COURS 13/02]])/Tableau156[[#This Row],[COURS 13/02]] -> -0.050682261 | T33: =1 -> 1
B34: 21 | C34: COVIVIO | D34: 0.02 | E34: 63.15 | F34: 62.75 | G34: 65.1 | H34: 64.1 | I34: 61.85 | J34: =ROUNDDOWN(D34*$J$2/Tableau156[[#This Row],[COURS 27/01]],0) -> 25336 | K34: =J34*Tableau156[[#This Row],[COURS 07/03]] -> 1567031.6 | L34: 1.43 | Q34: =L34*D34 -> 0.0286 | R34: =(Tableau156[[#This Row],[COURS 07/03]]-Tableau156[[#This Row],[COURS 13/02]])/Tableau156[[#This Row],[COURS 13/02]] -> -0.035101404
B35: 29 | C35: RENAULT | D35: =4% -> 0.04 | E35: 39.33 | F35: 15.88 | G35: 39.33 | H35: 40.85 | I35: 42.27 | J35: =ROUNDDOWN(D35*$J$2/Tableau156[[#This Row],[COURS 27/01]],0) -> 81362 | K35: =J35*Tableau156[[#This Row],[COURS 07/03]] -> 3439171.7 | L35: 1.67 | Q35: =L35*D35 -> 0.0668 | R35: =(Tableau156[[#This Row],[COURS 07/03]]-Tableau156[[#This Row],[COURS 13/02]])/Tableau156[[#This Row],[COURS 13/02]] -> 0.034761322
B36: 2 | C36: AIRBUS | D36: 0.04 | E36: 116.62 | F36: 112.56 | G36: 114 | H36: 114.3 | I36: 124.48 | J36: =ROUNDDOWN(D36*$J$2/Tableau156[[#This Row],[COURS 27/01]],0) -> 27439 | K36: =J36*Tableau156[[#This Row],[COURS 07/03]] -> 3415606.7 | L36: 1.7 | Q36: =L36*D36 -> 0.068 | R36: =(Tableau156[[#This Row],[COURS 07/03]]-Tableau156[[#This Row],[COURS 13/02]])/Tableau156[[#This Row],[COURS 13/02]] -> 0.089063867
B37: 26 | C37: CATANA GROUPE | D37: 0.01 | E37: 6.48 | F37: 6.5 | G37: 7 | H37: 7.13 | I37: 7.6 | J37: =ROUNDDOWN(D37*$J$2/Tableau156[[#This Row],[COURS 27/01]],0) -> 123456 | K37: =J37*Tableau156[[#This Row],[COURS 07/03]] -> 938265.6 | L37: 1.7 | Q37: =L37*D37 -> 0.017 | R37: =(Tableau156[[#This Row],[COURS 07/03]]-Tableau156[[#This Row],[COURS 13/02]])/Tableau156[[#This Row],[COURS 13/02]] -> 0.065918654 | T37: =8093*148.26 -> 1199868.2
B38: 18 | C38: BNP PARIBAS | D38: 0.045 | E38: 62.03 | F38: 62.66 | G38: 61.24 | H38: 63.75 | I38: 65.06 | J38: =ROUNDDOWN(D38*$J$2/Tableau156[[#This Row],[COURS 27/01]],0) -> 58036 | K38: =J38*Tableau156[[#This Row],[COURS 07/03]] -> 3775822.2 | L38: 1.73 | Q38: =L38*D38 -> 0.07785 | R38: =(Tableau156[[#This Row],[COURS 07/03]]-Tableau156[[#This Row],[COURS 13/02]])/Tableau156[[#This Row],[COURS 13/02]] -> 0.02054902
B39: TOTAL | D39: =SUM(D10:D38) -> 1 | K39: =SUM(K10:K38) -> 83216909 | L39: Beta Pondéré | Q39: =SUM(Q10:Q38) -> 0.994061 | R39: =SUM(Tableau156[Performance]) -> 0.65636949
B41: Obligations
B43: Libellé | C43: Taux Coupon | D43: Maturité | E43: Date Coupon | J43: Rendement | K43: Date achat | L43: Cours du 27/01 | M43: Cours du 31/01 | N43: Cours du 07/02 | O43: Cours 13/02 | P43: Cours 07/03 | Q43: Pondération | R43: Nbre de titre | S43: Montant | T43: Performance
B44: OAT 10 ans | C44: 0.02 | D44: 48543 | E44: 45255 | J44: 0.02702 | K44: 44953 | L44: 100 | M44: 93.7 | N44: 93.73 | O44: 93.08 | P44: 89.79 | Q44: 0.6 | R44: =ROUNDDOWN(Q44*$J$3/L44,0) -> 60000 | S44: =R44*P44 -> 5387400 | T44: =(P44-O44)/O44 -> -0.035345939
B45: OAT 5 ans | C45: 0.0075 | D45: 46898 | E45: 45071 | J45: 0.025388 | K45: 44953 | L45: 91.49 | M45: 90.72 | N45: 91.11 | O45: 90.65 | P45: 88.57 | Q45: 0.4 | R45: =ROUNDDOWN(Q45*$J$3/L45,0) -> 43720 | S45: =R45*P45 -> 3872280.4 | T45: =(P45-O45)/O45 -> -0.022945394
...

Sheet Composant du portefeuile 
C1: Date
B2: Composants du portefeuille | C2: 44953 | D2: 44957 | E2: 44964 | F2: 44970 | G2: 44992
B3: Actions | C3: =79997062.37 -> 79997062 | D3: ='31.01'!H39 -> 79823619 | E3: ='07.02'!I39 -> 81716639 | F3: ='13.02'!J39 -> 81588355 | G3: ='07.03'!K39 -> 83216909
B4: Obligations | C4: =9999942.8 -> 9999942.8 | D4: ='31.01'!N46 -> 9588278.4 | E4: ='07.02'!O46 -> 9607129.2 | F4: ='13.02'!Q46 -> 9548018 | G4: ='07.03'!S46 -> 9259680.4
B5: Monétaire | C5: =100000000-SUM(C3:C4) -> 10002995 | D5: =C5 -> 10002995 | E5: =D5 -> 10002995 | F5: =D5 -> 10002995 | G5: =D5 -> 10002995
B6: Valeur du portefeuillle | C6: =SUM(C3:C5) -> 100000000 | D6: =SUM(D3:D5) -> 99414893 | E6: =SUM(E3:E5) -> 1.0132676e+08 | F6: =SUM(F3:F5) -> 1.0113937e+08 | G6: =SUM(G3:G5) -> 1.0247958e+08
B7: Variation du portefeuille | D7: =(D6-C6)/C6 -> -0.0058510735 | E7: =(E6-D6)/D6 -> 0.019231222 | F7: =(F6-E6)/E6 -> -0.0018494118 | G7: =(G6-F6)/F6 -> 0.01325119
B8: Performance du portefeuille
B9: Benchmark : CAC 40 | C9: 6900.889 | D9: 7575.0898 | E9: 7145.8398 | F9: 7147.48 | G9: 7355.8701
B10: Variation du benchmark | D10: =(D9-C9)/C9 -> 0.097697673 | E10: =(E9-D9)/D9 -> -0.056665995 | F10: =(F9-E9)/E9 -> 0.00022953215 | G10: =(G9-F9)/F9 -> 0.029155744
B11: Comparaison benchmark/portefeuille | D11: sous performance | E11: sur performance | F11: sous performance | G11: sous performance
B13: Variation global benchmark (21/01 - 07/03) | C13: =(G9-C9)/C9 -> 0.065930795
B14: variation global Portefeuille (21/01 - 07/03) | C14: =(G6-C6)/C6 -> 0.024795847
